<?xml version="1.0"?>
<robot name="aid" xmlns:xacro="http://ros.org/wiki/xacro">

  <!-- Defining the colors used in this robot -->
  <material name="Black">
    <color rgba="0 0 0 1"/>
  </material>

  <material name="White">
    <color rgba="1 1 1 1"/>
  </material>

  <material name="Blue">
    <color rgba="0 0 1 1"/>
  </material>

  <material name="Red">
    <color rgba="1 0 0 1"/>
  </material>

  <material name="Grey">
    <color rgba="0.96 0.96 0.96 1"/>
  </material>

  <!-- Constants -->
  <xacro:property name="M_PI" value="3.1415926"/>
  <xacro:property name="R_LIMIT" value="3.05"/>

  <!-- //////// DYNAMICS PARAM /////// -->

  <xacro:macro name="L0_Shoulder_Inertia">
    <origin xyz="-0.065339 -1.9234E-15 0.93756"
            rpy="0 0 0" />
    <mass value="37.032" />
    <inertia  ixx="14.546"
              ixy="-2.0675E-14"
              ixz="1.736"
              iyy="15.487"
              iyz="5.0978E-14"
              izz="1.5176" />
  </xacro:macro>

  <xacro:macro name="L1_BigArm_Inertia">
    <origin xyz="0.01517 -0.19923 -0.016519"
            rpy="0 0 0" />
    <mass value="38.9" />
    <inertia  ixx="0.69607"
              ixy="-0.10626"
              ixz="-0.0097479"
              iyy="0.23375"
              iyz="-0.048863"
              izz="0.59973" />
  </xacro:macro> 

  <xacro:macro name="L2_Elbow_Inertia">
    <origin xyz="1.6653E-16 -0.064421 0.015667"
            rpy="0 0 0" />
    <mass value="11.18" />
    <inertia  ixx="0.14822"
              ixy="8.3834E-17"
              ixz="7.8495E-18"
              iyy="0.12818"
              iyz="-0.012852"
              izz="0.044066" />
  </xacro:macro> 

  <xacro:macro name="L3_ForeArm_Inertia">
    <origin xyz="0.0061768 0.014912 0.020282"
            rpy="0 0 0" />
    <mass value="16.17" />
    <inertia  ixx="0.232059974154934"
              ixy="-0.005837242059444"
              ixz="-0.008987732435557"
              iyy="0.220384023668639"
              iyz="-0.021698571720057"
              izz="0.049915146568727" />
  </xacro:macro> 

  <xacro:macro name="L4_Wrist1_Inertia">
    <origin xyz="-3.3307E-15 -0.071299 -0.012584"
            rpy="0 0 0" />
    <mass value="10.14" />
    <inertia  ixx="0.10127"
              ixy="1.077E-15"
              ixz="-2.5356E-15"
              iyy="0.08693"
              iyz="0.010069"
              izz="0.034066" />
  </xacro:macro>

  <xacro:macro name="L5_Wrist2_Inertia">
    <origin xyz="0.0071606 -0.17208 0.017287"
            rpy="0 0 0" />
    <mass value="10.91" />
    <inertia  ixx="0.124071088191495"
              ixy="0.006790844685897"
              ixz="-0.005624086647179"
              iyy="0.033104277204787"
              iyz="0.016394484860184"
              izz="0.112821711433457" />
  </xacro:macro>

  <xacro:macro name="L6_Palm_Inertia">
    <origin xyz="-0.024868 -0.0455 -4.6629E-15"
            rpy="0 0 0" />
    <mass value="5.91" />
    <inertia  ixx="0.014677242234883"
              ixy="0.006892601314097"
              ixz="-8.11009281382099E-15"
              iyy="0.050065553207131"
              iyz="-4.66386004410954E-15"
              izz="0.05589707544569" />
  </xacro:macro>

  <!--////////// BASE AND SHOULDER ///////////-->

  <link name="L0">
    <inertia>
      <xacro:L0_Shoulder_Inertia/>
    </inertia>
    <visual>
      <origin xyz="0 0 0" rpy="0 0 0" />
      <geometry>
        <mesh filename="package://aid/meshes/L0.STL" />
      </geometry>
      <material name="">
        <color  rgba="0.75294 0.75294 0.75294 1" />
      </material>
    </visual>
    <collision>
      <origin xyz="0 0 0"
              rpy="0 0 0" />
      <geometry>
        <mesh filename="package://aid/meshes/L0.STL" />
      </geometry>
    </collision>
  </link>

  
  <!--/////////////// BIG ARM //////////////-->

  <link name="L1">
    <inertia>
      <xacro:L1_BigArm_Inertia/>
    </inertia>
    <visual>
      <origin xyz="0 0 0" rpy="0 0 0" />
      <geometry>
        <mesh filename="package://aid/meshes/L1.STL" />
      </geometry>
      <material name="">
        <color  rgba="0.75294 0.75294 0.75294 1" />
      </material>
    </visual>
    <collision>
      <origin xyz="0 0 0" rpy="0 0 0" />
      <geometry>
        <mesh filename="package://aid/meshes/L1.STL" />
      </geometry>
    </collision>
  </link> 


  <!--////////////////// SHOULDER JOINT /////////////////////-->

  <joint name="J1" type="revolute">
    <origin xyz="-0.4605 0 1.655" rpy="1.5708 0 0" />
    <parent link="L0" />
    <child  link="L1" />
    <axis xyz="1 0 0" />
    <limit  lower="-${R_LIMIT}" upper="${R_LIMIT}"  effort="1000" velocity="3.1416" />
  </joint>  


  <!--/////////// ELBOW ////////////-->

  <link name="L2">
    <inertia>
      <xacro:L2_Elbow_Inertia/>
    </inertia>
    <visual>
      <origin xyz="0 0 0" rpy="0 0 0" />
      <geometry>
        <mesh filename="package://aid/meshes/L2.STL" />
      </geometry>
      <material name="">
        <color  rgba="0.75294 0.75294 0.75294 1" />
      </material>
    </visual>
    <collision>
      <origin xyz="0 0 0" rpy="0 0 0" />
      <geometry>
        <mesh filename="package://aid/meshes/L2.STL" />
      </geometry>
    </collision>
  </link> 


  <!--///////////////// BIGARM JOINT ///////////////////////////-->

  <joint name="J2" type="revolute">
    <origin xyz="0 -0.275 -0.015" rpy="0 0 0" />
    <parent link="L1" />
    <child  link="L2" />
    <axis xyz="0 0 1" />
    <limit  lower="-${R_LIMIT}" upper="${R_LIMIT}"  effort="1000" velocity="3.1416" />
  </joint>  


  <!--/////////// ELBOW ////////////-->

  <link name="L3">
    <inertia>
      <xacro:L3_ForeArm_Inertia/>
    </inertia>
    <visual>
      <origin xyz="0 0 0" rpy="0 0 0" />
      <geometry>
        <mesh filename="package://aid/meshes/L3.STL" />
      </geometry>
      <material name="">
        <color  rgba="0.75294 0.75294 0.75294 1" />
      </material>
    </visual>
    <collision>
      <origin xyz="0 0 0" rpy="0 0 0" />
      <geometry>
        <mesh filename="package://aid/meshes/L3.STL" />
      </geometry>
    </collision>
  </link> 


  <!--//////////////////// ELBOW JOINT ////////////////////////-->

  <joint name="J3" type="revolute">
    <origin xyz="0 -0.332 0" rpy="1.5708 -0.7854 0" />
    <parent link="L2" />
    <child  link="L3" />
    <axis xyz="0 0 -1" />
    <limit  lower="-${R_LIMIT}" upper="${R_LIMIT}"  effort="800" velocity="3.1416" />
  </joint>  


  <!--//////////// WRIST1 //////////////////////-->

  <link name="L4">
    <inertia>
      <xacro:L4_Wrist1_Inertia/>
    </inertia>
    <visual>
      <origin xyz="0 0 0" rpy="0 0 0" />
      <geometry>
        <mesh filename="package://aid/meshes/L4.STL" />
      </geometry>
      <material name="">
        <color  rgba="0.75294 0.75294 0.75294 1" />
      </material>
    </visual>
    <collision>
      <origin xyz="0 0 0" rpy="0 0 0" />
      <geometry>
        <mesh filename="package://aid/meshes/L4.STL" />
      </geometry>
    </collision>
  </link> 


  <!--/////////////////// WRIST1 JOINT //////////////////////-->

  <joint name="J4" type="revolute">
    <origin xyz="0.0019134 0.0046194 0.11"  rpy="-1.5708 0 -0.3927" />
    <parent link="L3" />
    <child  link="L4" />
    <axis xyz="0 0 1" />
    <limit  lower="-${R_LIMIT}" upper="${R_LIMIT}"  effort="600" velocity="3.1416" />
  </joint> 


  <!--///////////////// WRIST2 ////////////////////-->

  <link name="L5">
    <inertia>
      <xacro:L5_Wrist2_Inertia/>
    </inertia>
    <visual>
      <origin xyz="0 0 0" rpy="0 0 0" />
      <geometry>
        <mesh filename="package://aid/meshes/L5.STL" />
      </geometry>
      <material name="">
        <color  rgba="0.75294 0.75294 0.75294 1" />
      </material>
    </visual>
    <collision>
      <origin xyz="0 0 0" rpy="0 0 0" />
      <geometry>
        <mesh filename="package://aid/meshes/L5.STL" />
      </geometry>
    </collision>
  </link> 


  <!--////////////////// WRIST2 JOINT ///////////////////////-->

  <joint name="J5" type="revolute">
    <origin  xyz="0 -0.145 0"  rpy="0 -8.6098E-14 0" />
    <parent link="L4" />
    <child  link="L5" />
    <axis xyz="0 1 0" />
    <limit  lower="-${R_LIMIT}" upper="${R_LIMIT}"  effort="400" velocity="3.1416" />
  </joint> 


  <!--///////////////// PALM //////////////////////-->

  <link name="L6">
    <inertia>
      <xacro:L5_Wrist2_Inertia/>
    </inertia>
    <visual>
      <origin xyz="0 0 0" rpy="0 0 0" />
      <geometry>
        <mesh filename="package://aid/meshes/L6.STL" />
      </geometry>
      <material name="">
        <color  rgba="0.75294 0.75294 0.75294 1" />
      </material>
    </visual>
    <collision>
      <origin xyz="0 0 0" rpy="0 0 0" />
      <geometry>
        <mesh filename="package://aid/meshes/L6.STL" />
      </geometry>
    </collision>
  </link> 


  <!--///////////////// PALM JOINT ////////////////////////-->

  <joint name="J6" type="revolute">
    <origin xyz="0.0082277 -0.259 0.019863" rpy="0 -1.1781 0" />
    <parent link="L5" />
    <child  link="L6" />
    <axis xyz="1 0 0" />
    <limit  lower="-${R_LIMIT}" upper="${R_LIMIT}"  effort="200" velocity="3.1416" />
  </joint> 


  <link name="world" />
  <joint name="world_joint" type="fixed">
    <parent link="world" />
    <child link = "L0" />
    <origin xyz="0.0 0.0 0.0" rpy="0.0 0.0 0.0" />
  </joint>


  <!--////////////////////////////////// Transmissions for ROS Control //////////////////////////-->

  <xacro:macro name="aid_arm_transmission" params="joint_name">
    <transmission name="${joint_name}_trans">
      <type>transmission_interface/SimpleTransmission</type>
        <joint name="${joint_name}">
          <hardwareInterface>hardware_interface/PositionJointInterface</hardwareInterface>
        </joint>
      <actuator name="${joint_name}_motor">
        <mechanicalReduction>1</mechanicalReduction>
      </actuator>
    </transmission>
  </xacro:macro>


  <xacro:aid_arm_transmission joint_name="J1"/>
  <xacro:aid_arm_transmission joint_name="J2"/>
  <xacro:aid_arm_transmission joint_name="J3"/>
  <xacro:aid_arm_transmission joint_name="J4"/>
  <xacro:aid_arm_transmission joint_name="J5"/>
  <xacro:aid_arm_transmission joint_name="J6"/>

  <!-- ros_control plugin -->
  <gazebo>
    <plugin name="gazebo_ros_control" filename="libgazebo_ros_control.so">
      <robotNamespace>/aid</robotNamespace>
      <robotSimType>gazebo_ros_control/DefaultRobotHWSim</robotSimType>
      <legacyModeNS>true</legacyModeNS>
    </plugin>
  </gazebo>

</robot>
