<?xml version="1.0" ?>
<!-- =================================================================================== -->
<!-- |    This document was autogenerated by xacro from aid.xacro                      | -->
<!-- |    EDITING THIS FILE BY HAND IS NOT RECOMMENDED                                 | -->
<!-- =================================================================================== -->
<robot name="aid" xmlns:xacro="http://ros.org/wiki/xacro">
  <!-- Defining the colors used in this robot -->
  <!-- //////// DYNAMICS PARAM /////// -->
  <!--////////// BASE AND SHOULDER ///////////-->
  <link name="L0">
    <inertia>
      <origin rpy="0 0 0" xyz="-0.065339 -1.9234E-15 0.93756"/>
      <mass value="37.032"/>
      <inertia ixx="14.546" ixy="-2.0675E-14" ixz="1.736" iyy="15.487" iyz="5.0978E-14" izz="1.5176"/>
    </inertia>
    <visual>
      <origin rpy="0 0 0" xyz="0 0 0"/>
      <geometry>
        <mesh filename="package://aid/meshes/L0.STL"/>
      </geometry>
      <material name="">
        <color rgba="0.75294 0.75294 0.75294 1"/>
      </material>
    </visual>
    <collision>
      <origin rpy="0 0 0" xyz="0 0 0"/>
      <geometry>
        <mesh filename="package://aid/meshes/L0.STL"/>
      </geometry>
    </collision>
  </link>
  <!--/////////////// BIG ARM //////////////-->
  <link name="L1">
    <inertia>
      <origin rpy="0 0 0" xyz="0.01517 -0.19923 -0.016519"/>
      <mass value="38.9"/>
      <inertia ixx="0.69607" ixy="-0.10626" ixz="-0.0097479" iyy="0.23375" iyz="-0.048863" izz="0.59973"/>
    </inertia>
    <visual>
      <origin rpy="0 0 0" xyz="0 0 0"/>
      <geometry>
        <mesh filename="package://aid/meshes/L1.STL"/>
      </geometry>
      <material name="">
        <color rgba="0.75294 0.75294 0.75294 1"/>
      </material>
    </visual>
    <collision>
      <origin rpy="0 0 0" xyz="0 0 0"/>
      <geometry>
        <mesh filename="package://aid/meshes/L1.STL"/>
      </geometry>
    </collision>
  </link>
  <!--////////////////// SHOULDER JOINT /////////////////////-->
  <joint name="J1" type="revolute">
    <origin rpy="1.5708 0 0" xyz="-0.4605 0 1.655"/>
    <parent link="L0"/>
    <child link="L1"/>
    <axis xyz="1 0 0"/>
    <limit effort="1000" lower="-3.05" upper="3.05" velocity="3.1416"/>
  </joint>
  <!--/////////// ELBOW ////////////-->
  <link name="L2">
    <inertia>
      <origin rpy="0 0 0" xyz="1.6653E-16 -0.064421 0.015667"/>
      <mass value="11.18"/>
      <inertia ixx="0.14822" ixy="8.3834E-17" ixz="7.8495E-18" iyy="0.12818" iyz="-0.012852" izz="0.044066"/>
    </inertia>
    <visual>
      <origin rpy="0 0 0" xyz="0 0 0"/>
      <geometry>
        <mesh filename="package://aid/meshes/L2.STL"/>
      </geometry>
      <material name="">
        <color rgba="0.75294 0.75294 0.75294 1"/>
      </material>
    </visual>
    <collision>
      <origin rpy="0 0 0" xyz="0 0 0"/>
      <geometry>
        <mesh filename="package://aid/meshes/L2.STL"/>
      </geometry>
    </collision>
  </link>
  <!--///////////////// BIGARM JOINT ///////////////////////////-->
  <joint name="J2" type="revolute">
    <origin rpy="0 0 0" xyz="0 -0.275 -0.015"/>
    <parent link="L1"/>
    <child link="L2"/>
    <axis xyz="0 0 1"/>
    <limit effort="1000" lower="-3.05" upper="3.05" velocity="3.1416"/>
  </joint>
  <!--/////////// ELBOW ////////////-->
  <link name="L3">
    <inertia>
      <origin rpy="0 0 0" xyz="0.0061768 0.014912 0.020282"/>
      <mass value="16.17"/>
      <inertia ixx="0.232059974154934" ixy="-0.005837242059444" ixz="-0.008987732435557" iyy="0.220384023668639" iyz="-0.021698571720057" izz="0.049915146568727"/>
    </inertia>
    <visual>
      <origin rpy="0 0 0" xyz="0 0 0"/>
      <geometry>
        <mesh filename="package://aid/meshes/L3.STL"/>
      </geometry>
      <material name="">
        <color rgba="0.75294 0.75294 0.75294 1"/>
      </material>
    </visual>
    <collision>
      <origin rpy="0 0 0" xyz="0 0 0"/>
      <geometry>
        <mesh filename="package://aid/meshes/L3.STL"/>
      </geometry>
    </collision>
  </link>
  <!--//////////////////// ELBOW JOINT ////////////////////////-->
  <joint name="J3" type="revolute">
    <origin rpy="1.5708 -0.7854 0" xyz="0 -0.332 0"/>
    <parent link="L2"/>
    <child link="L3"/>
    <axis xyz="0 0 -1"/>
    <limit effort="800" lower="-3.05" upper="3.05" velocity="3.1416"/>
  </joint>
  <!--//////////// WRIST1 //////////////////////-->
  <link name="L4">
    <inertia>
      <origin rpy="0 0 0" xyz="-3.3307E-15 -0.071299 -0.012584"/>
      <mass value="10.14"/>
      <inertia ixx="0.10127" ixy="1.077E-15" ixz="-2.5356E-15" iyy="0.08693" iyz="0.010069" izz="0.034066"/>
    </inertia>
    <visual>
      <origin rpy="0 0 0" xyz="0 0 0"/>
      <geometry>
        <mesh filename="package://aid/meshes/L4.STL"/>
      </geometry>
      <material name="">
        <color rgba="0.75294 0.75294 0.75294 1"/>
      </material>
    </visual>
    <collision>
      <origin rpy="0 0 0" xyz="0 0 0"/>
      <geometry>
        <mesh filename="package://aid/meshes/L4.STL"/>
      </geometry>
    </collision>
  </link>
  <!--/////////////////// WRIST1 JOINT //////////////////////-->
  <joint name="J4" type="revolute">
    <origin rpy="-1.5708 0 -0.3927" xyz="0.0019134 0.0046194 0.11"/>
    <parent link="L3"/>
    <child link="L4"/>
    <axis xyz="0 0 1"/>
    <limit effort="600" lower="-3.05" upper="3.05" velocity="3.1416"/>
  </joint>
  <!--///////////////// WRIST2 ////////////////////-->
  <link name="L5">
    <inertia>
      <origin rpy="0 0 0" xyz="0.0071606 -0.17208 0.017287"/>
      <mass value="10.91"/>
      <inertia ixx="0.124071088191495" ixy="0.006790844685897" ixz="-0.005624086647179" iyy="0.033104277204787" iyz="0.016394484860184" izz="0.112821711433457"/>
    </inertia>
    <visual>
      <origin rpy="0 0 0" xyz="0 0 0"/>
      <geometry>
        <mesh filename="package://aid/meshes/L5.STL"/>
      </geometry>
      <material name="">
        <color rgba="0.75294 0.75294 0.75294 1"/>
      </material>
    </visual>
    <collision>
      <origin rpy="0 0 0" xyz="0 0 0"/>
      <geometry>
        <mesh filename="package://aid/meshes/L5.STL"/>
      </geometry>
    </collision>
  </link>
  <!--////////////////// WRIST2 JOINT ///////////////////////-->
  <joint name="J5" type="revolute">
    <origin rpy="0 -8.6098E-14 0" xyz="0 -0.145 0"/>
    <parent link="L4"/>
    <child link="L5"/>
    <axis xyz="0 1 0"/>
    <limit effort="400" lower="-3.05" upper="3.05" velocity="3.1416"/>
  </joint>
  <!--///////////////// PALM //////////////////////-->
  <link name="L6">
    <inertia>
      <origin rpy="0 0 0" xyz="0.0071606 -0.17208 0.017287"/>
      <mass value="10.91"/>
      <inertia ixx="0.124071088191495" ixy="0.006790844685897" ixz="-0.005624086647179" iyy="0.033104277204787" iyz="0.016394484860184" izz="0.112821711433457"/>
    </inertia>
    <visual>
      <origin rpy="0 0 0" xyz="0 0 0"/>
      <geometry>
        <mesh filename="package://aid/meshes/L6.STL"/>
      </geometry>
      <material name="">
        <color rgba="0.75294 0.75294 0.75294 1"/>
      </material>
    </visual>
    <collision>
      <origin rpy="0 0 0" xyz="0 0 0"/>
      <geometry>
        <mesh filename="package://aid/meshes/L6.STL"/>
      </geometry>
    </collision>
  </link>
  <!--///////////////// PALM JOINT ////////////////////////-->
  <joint name="J6" type="revolute">
    <origin rpy="0 -1.1781 0" xyz="0.0082277 -0.259 0.019863"/>
    <parent link="L5"/>
    <child link="L6"/>
    <axis xyz="1 0 0"/>
    <limit effort="200" lower="-3.05" upper="3.05" velocity="3.1416"/>
  </joint>
  <link name="world"/>
  <joint name="world_joint" type="fixed">
    <parent link="world"/>
    <child link="L0"/>
    <origin rpy="0.0 0.0 0.0" xyz="0.0 0.0 0.0"/>
  </joint>
  <!--////////////////////////////////// Transmissions for ROS Control //////////////////////////-->
  <transmission name="J1_trans">
    <type>transmission_interface/SimpleTransmission</type>
    <joint name="J1">
      <hardwareInterface>hardware_interface/PositionJointInterface</hardwareInterface>
    </joint>
    <actuator name="J1_motor">
      <mechanicalReduction>1</mechanicalReduction>
    </actuator>
  </transmission>
  <transmission name="J2_trans">
    <type>transmission_interface/SimpleTransmission</type>
    <joint name="J2">
      <hardwareInterface>hardware_interface/PositionJointInterface</hardwareInterface>
    </joint>
    <actuator name="J2_motor">
      <mechanicalReduction>1</mechanicalReduction>
    </actuator>
  </transmission>
  <transmission name="J3_trans">
    <type>transmission_interface/SimpleTransmission</type>
    <joint name="J3">
      <hardwareInterface>hardware_interface/PositionJointInterface</hardwareInterface>
    </joint>
    <actuator name="J3_motor">
      <mechanicalReduction>1</mechanicalReduction>
    </actuator>
  </transmission>
  <transmission name="J4_trans">
    <type>transmission_interface/SimpleTransmission</type>
    <joint name="J4">
      <hardwareInterface>hardware_interface/PositionJointInterface</hardwareInterface>
    </joint>
    <actuator name="J4_motor">
      <mechanicalReduction>1</mechanicalReduction>
    </actuator>
  </transmission>
  <transmission name="J5_trans">
    <type>transmission_interface/SimpleTransmission</type>
    <joint name="J5">
      <hardwareInterface>hardware_interface/PositionJointInterface</hardwareInterface>
    </joint>
    <actuator name="J5_motor">
      <mechanicalReduction>1</mechanicalReduction>
    </actuator>
  </transmission>
  <transmission name="J6_trans">
    <type>transmission_interface/SimpleTransmission</type>
    <joint name="J6">
      <hardwareInterface>hardware_interface/PositionJointInterface</hardwareInterface>
    </joint>
    <actuator name="J6_motor">
      <mechanicalReduction>1</mechanicalReduction>
    </actuator>
  </transmission>
  <!-- ros_control plugin -->
  <gazebo>
    <plugin filename="libgazebo_ros_control.so" name="gazebo_ros_control">
      <robotNamespace>/aid</robotNamespace>
      <robotSimType>gazebo_ros_control/DefaultRobotHWSim</robotSimType>
      <legacyModeNS>true</legacyModeNS>
    </plugin>
  </gazebo>
</robot>
